2018-11-02 23:29:48,809 INFO: Auth startup [in C:\Users\h84173\Documents\INSTALL\EasyPHP\data\localweb\Flask_projects\auth_project\authapp\__init__.py:33]
2018-11-02 23:30:04,503 ERROR: Exception on /edit_profile [POST] [in c:\users\h84173\documents\install\python\python37-32\lib\site-packages\flask\app.py:1761]
Traceback (most recent call last):
  File "c:\users\h84173\documents\install\python\python37-32\lib\site-packages\sqlalchemy\engine\base.py", line 1193, in _execute_context
    context)
  File "c:\users\h84173\documents\install\python\python37-32\lib\site-packages\sqlalchemy\engine\default.py", line 509, in do_execute
    cursor.execute(statement, parameters)
sqlite3.IntegrityError: UNIQUE constraint failed: user.username

The above exception was the direct cause of the following exception:

Traceback (most recent call last):
  File "c:\users\h84173\documents\install\python\python37-32\lib\site-packages\flask\app.py", line 2292, in wsgi_app
    response = self.full_dispatch_request()
  File "c:\users\h84173\documents\install\python\python37-32\lib\site-packages\flask\app.py", line 1815, in full_dispatch_request
    rv = self.handle_user_exception(e)
  File "c:\users\h84173\documents\install\python\python37-32\lib\site-packages\flask\app.py", line 1718, in handle_user_exception
    reraise(exc_type, exc_value, tb)
  File "c:\users\h84173\documents\install\python\python37-32\lib\site-packages\flask\_compat.py", line 35, in reraise
    raise value
  File "c:\users\h84173\documents\install\python\python37-32\lib\site-packages\flask\app.py", line 1813, in full_dispatch_request
    rv = self.dispatch_request()
  File "c:\users\h84173\documents\install\python\python37-32\lib\site-packages\flask\app.py", line 1799, in dispatch_request
    return self.view_functions[rule.endpoint](**req.view_args)
  File "c:\users\h84173\documents\install\python\python37-32\lib\site-packages\flask_login\utils.py", line 261, in decorated_view
    return func(*args, **kwargs)
  File "C:\Users\h84173\Documents\INSTALL\EasyPHP\data\localweb\Flask_projects\auth_project\authapp\routes.py", line 74, in edit_profile
    db.session.commit()
  File "c:\users\h84173\documents\install\python\python37-32\lib\site-packages\sqlalchemy\orm\scoping.py", line 153, in do
    return getattr(self.registry(), name)(*args, **kwargs)
  File "c:\users\h84173\documents\install\python\python37-32\lib\site-packages\sqlalchemy\orm\session.py", line 943, in commit
    self.transaction.commit()
  File "c:\users\h84173\documents\install\python\python37-32\lib\site-packages\sqlalchemy\orm\session.py", line 467, in commit
    self._prepare_impl()
  File "c:\users\h84173\documents\install\python\python37-32\lib\site-packages\sqlalchemy\orm\session.py", line 447, in _prepare_impl
    self.session.flush()
  File "c:\users\h84173\documents\install\python\python37-32\lib\site-packages\sqlalchemy\orm\session.py", line 2254, in flush
    self._flush(objects)
  File "c:\users\h84173\documents\install\python\python37-32\lib\site-packages\sqlalchemy\orm\session.py", line 2380, in _flush
    transaction.rollback(_capture_exception=True)
  File "c:\users\h84173\documents\install\python\python37-32\lib\site-packages\sqlalchemy\util\langhelpers.py", line 66, in __exit__
    compat.reraise(exc_type, exc_value, exc_tb)
  File "c:\users\h84173\documents\install\python\python37-32\lib\site-packages\sqlalchemy\util\compat.py", line 249, in reraise
    raise value
  File "c:\users\h84173\documents\install\python\python37-32\lib\site-packages\sqlalchemy\orm\session.py", line 2344, in _flush
    flush_context.execute()
  File "c:\users\h84173\documents\install\python\python37-32\lib\site-packages\sqlalchemy\orm\unitofwork.py", line 391, in execute
    rec.execute(self)
  File "c:\users\h84173\documents\install\python\python37-32\lib\site-packages\sqlalchemy\orm\unitofwork.py", line 556, in execute
    uow
  File "c:\users\h84173\documents\install\python\python37-32\lib\site-packages\sqlalchemy\orm\persistence.py", line 177, in save_obj
    mapper, table, update)
  File "c:\users\h84173\documents\install\python\python37-32\lib\site-packages\sqlalchemy\orm\persistence.py", line 768, in _emit_update_statements
    execute(statement, multiparams)
  File "c:\users\h84173\documents\install\python\python37-32\lib\site-packages\sqlalchemy\engine\base.py", line 948, in execute
    return meth(self, multiparams, params)
  File "c:\users\h84173\documents\install\python\python37-32\lib\site-packages\sqlalchemy\sql\elements.py", line 269, in _execute_on_connection
    return connection._execute_clauseelement(self, multiparams, params)
  File "c:\users\h84173\documents\install\python\python37-32\lib\site-packages\sqlalchemy\engine\base.py", line 1060, in _execute_clauseelement
    compiled_sql, distilled_params
  File "c:\users\h84173\documents\install\python\python37-32\lib\site-packages\sqlalchemy\engine\base.py", line 1200, in _execute_context
    context)
  File "c:\users\h84173\documents\install\python\python37-32\lib\site-packages\sqlalchemy\engine\base.py", line 1413, in _handle_dbapi_exception
    exc_info
  File "c:\users\h84173\documents\install\python\python37-32\lib\site-packages\sqlalchemy\util\compat.py", line 265, in raise_from_cause
    reraise(type(exception), exception, tb=exc_tb, cause=cause)
  File "c:\users\h84173\documents\install\python\python37-32\lib\site-packages\sqlalchemy\util\compat.py", line 248, in reraise
    raise value.with_traceback(tb)
  File "c:\users\h84173\documents\install\python\python37-32\lib\site-packages\sqlalchemy\engine\base.py", line 1193, in _execute_context
    context)
  File "c:\users\h84173\documents\install\python\python37-32\lib\site-packages\sqlalchemy\engine\default.py", line 509, in do_execute
    cursor.execute(statement, parameters)
sqlalchemy.exc.IntegrityError: (sqlite3.IntegrityError) UNIQUE constraint failed: user.username [SQL: 'UPDATE user SET username=? WHERE user.id = ?'] [parameters: ('susan', 5)] (Background on this error at: http://sqlalche.me/e/gkpj)
2018-11-02 23:35:10,304 INFO: Auth startup [in C:\Users\h84173\Documents\INSTALL\EasyPHP\data\localweb\Flask_projects\auth_project\authapp\__init__.py:33]
2018-11-02 23:52:41,331 INFO: Auth startup [in C:\Users\h84173\Documents\INSTALL\EasyPHP\data\localweb\Flask_projects\auth_project\authapp\__init__.py:33]
2018-11-02 23:53:04,799 ERROR: Exception on /reset_password_request [GET] [in c:\users\h84173\documents\install\python\python37-32\lib\site-packages\flask\app.py:1761]
Traceback (most recent call last):
  File "c:\users\h84173\documents\install\python\python37-32\lib\site-packages\flask\app.py", line 2292, in wsgi_app
    response = self.full_dispatch_request()
  File "c:\users\h84173\documents\install\python\python37-32\lib\site-packages\flask\app.py", line 1815, in full_dispatch_request
    rv = self.handle_user_exception(e)
  File "c:\users\h84173\documents\install\python\python37-32\lib\site-packages\flask\app.py", line 1718, in handle_user_exception
    reraise(exc_type, exc_value, tb)
  File "c:\users\h84173\documents\install\python\python37-32\lib\site-packages\flask\_compat.py", line 35, in reraise
    raise value
  File "c:\users\h84173\documents\install\python\python37-32\lib\site-packages\flask\app.py", line 1813, in full_dispatch_request
    rv = self.dispatch_request()
  File "c:\users\h84173\documents\install\python\python37-32\lib\site-packages\flask\app.py", line 1799, in dispatch_request
    return self.view_functions[rule.endpoint](**req.view_args)
  File "C:\Users\h84173\Documents\INSTALL\EasyPHP\data\localweb\Flask_projects\auth_project\authapp\routes.py", line 90, in reset_password_request
    return render_template('reset_password_request', title='Reset Password', form=form)
  File "c:\users\h84173\documents\install\python\python37-32\lib\site-packages\flask\templating.py", line 134, in render_template
    return _render(ctx.app.jinja_env.get_or_select_template(template_name_or_list),
  File "c:\users\h84173\documents\install\python\python37-32\lib\site-packages\jinja2\environment.py", line 869, in get_or_select_template
    return self.get_template(template_name_or_list, parent, globals)
  File "c:\users\h84173\documents\install\python\python37-32\lib\site-packages\jinja2\environment.py", line 830, in get_template
    return self._load_template(name, self.make_globals(globals))
  File "c:\users\h84173\documents\install\python\python37-32\lib\site-packages\jinja2\environment.py", line 804, in _load_template
    template = self.loader.load(self, name, globals)
  File "c:\users\h84173\documents\install\python\python37-32\lib\site-packages\jinja2\loaders.py", line 113, in load
    source, filename, uptodate = self.get_source(environment, name)
  File "c:\users\h84173\documents\install\python\python37-32\lib\site-packages\flask\templating.py", line 58, in get_source
    return self._get_source_fast(environment, template)
  File "c:\users\h84173\documents\install\python\python37-32\lib\site-packages\flask\templating.py", line 86, in _get_source_fast
    raise TemplateNotFound(template)
jinja2.exceptions.TemplateNotFound: reset_password_request
2018-11-02 23:53:53,575 INFO: Auth startup [in C:\Users\h84173\Documents\INSTALL\EasyPHP\data\localweb\Flask_projects\auth_project\authapp\__init__.py:33]
2018-11-03 00:16:32,305 INFO: Auth startup [in C:\Users\h84173\Documents\INSTALL\EasyPHP\data\localweb\Flask_projects\auth_project\authapp\__init__.py:33]
